[2023-05-07T15:56:31.077-0300] {taskinstance.py:1090} INFO - Dependencies all met for dep_context=non-requeueable deps ti=<TaskInstance: bigdata_tp.TopCTR manual__2023-05-07T18:56:19.709637+00:00 [queued]>
[2023-05-07T15:56:31.088-0300] {taskinstance.py:1090} INFO - Dependencies all met for dep_context=requeueable deps ti=<TaskInstance: bigdata_tp.TopCTR manual__2023-05-07T18:56:19.709637+00:00 [queued]>
[2023-05-07T15:56:31.089-0300] {taskinstance.py:1288} INFO - 
--------------------------------------------------------------------------------
[2023-05-07T15:56:31.089-0300] {taskinstance.py:1289} INFO - Starting attempt 1 of 1
[2023-05-07T15:56:31.089-0300] {taskinstance.py:1290} INFO - 
--------------------------------------------------------------------------------
[2023-05-07T15:56:31.106-0300] {taskinstance.py:1309} INFO - Executing <Task(PythonOperator): TopCTR> on 2023-05-07 18:56:19.709637+00:00
[2023-05-07T15:56:31.130-0300] {standard_task_runner.py:55} INFO - Started process 2195 to run task
[2023-05-07T15:56:31.142-0300] {standard_task_runner.py:82} INFO - Running: ['airflow', 'tasks', 'run', 'bigdata_tp', 'TopCTR', 'manual__2023-05-07T18:56:19.709637+00:00', '--job-id', '66', '--raw', '--subdir', 'DAGS_FOLDER/dag.py', '--cfg-path', '/tmp/tmpsf4a861s']
[2023-05-07T15:56:31.146-0300] {standard_task_runner.py:83} INFO - Job 66: Subtask TopCTR
[2023-05-07T15:56:31.226-0300] {task_command.py:389} INFO - Running <TaskInstance: bigdata_tp.TopCTR manual__2023-05-07T18:56:19.709637+00:00 [running]> on host DESKTOP-02TA80M.localdomain
[2023-05-07T15:56:31.293-0300] {taskinstance.py:1516} INFO - Exporting the following env vars:
AIRFLOW_CTX_DAG_OWNER=airflow
AIRFLOW_CTX_DAG_ID=bigdata_tp
AIRFLOW_CTX_TASK_ID=TopCTR
AIRFLOW_CTX_EXECUTION_DATE=2023-05-07T18:56:19.709637+00:00
AIRFLOW_CTX_TRY_NUMBER=1
AIRFLOW_CTX_DAG_RUN_ID=manual__2023-05-07T18:56:19.709637+00:00
[2023-05-07T15:56:31.496-0300] {taskinstance.py:1776} ERROR - Task failed with exception
Traceback (most recent call last):
  File "/home/alanmatys/airflow_env/lib/python3.10/site-packages/pandas/core/indexes/base.py", line 3652, in get_loc
    return self._engine.get_loc(casted_key)
  File "pandas/_libs/index.pyx", line 147, in pandas._libs.index.IndexEngine.get_loc
  File "pandas/_libs/index.pyx", line 176, in pandas._libs.index.IndexEngine.get_loc
  File "pandas/_libs/hashtable_class_helper.pxi", line 7080, in pandas._libs.hashtable.PyObjectHashTable.get_item
  File "pandas/_libs/hashtable_class_helper.pxi", line 7088, in pandas._libs.hashtable.PyObjectHashTable.get_item
KeyError: 'sum'

The above exception was the direct cause of the following exception:

Traceback (most recent call last):
  File "/home/alanmatys/airflow_env/lib/python3.10/site-packages/airflow/operators/python.py", line 175, in execute
    return_value = self.execute_callable()
  File "/home/alanmatys/airflow_env/lib/python3.10/site-packages/airflow/operators/python.py", line 192, in execute_callable
    return self.python_callable(*self.op_args, **self.op_kwargs)
  File "/home/alanmatys/airflow/dags/dag.py", line 51, in TopCTR
    results["conversion"] = results["sum"] / results["count"]
  File "/home/alanmatys/airflow_env/lib/python3.10/site-packages/pandas/core/frame.py", line 3760, in __getitem__
    return self._getitem_multilevel(key)
  File "/home/alanmatys/airflow_env/lib/python3.10/site-packages/pandas/core/frame.py", line 3815, in _getitem_multilevel
    loc = self.columns.get_loc(key)
  File "/home/alanmatys/airflow_env/lib/python3.10/site-packages/pandas/core/indexes/multi.py", line 2812, in get_loc
    loc = self._get_level_indexer(key, level=0)
  File "/home/alanmatys/airflow_env/lib/python3.10/site-packages/pandas/core/indexes/multi.py", line 3160, in _get_level_indexer
    idx = self._get_loc_single_level_index(level_index, key)
  File "/home/alanmatys/airflow_env/lib/python3.10/site-packages/pandas/core/indexes/multi.py", line 2752, in _get_loc_single_level_index
    return level_index.get_loc(key)
  File "/home/alanmatys/airflow_env/lib/python3.10/site-packages/pandas/core/indexes/base.py", line 3654, in get_loc
    raise KeyError(key) from err
KeyError: 'sum'
[2023-05-07T15:56:31.517-0300] {taskinstance.py:1327} INFO - Marking task as FAILED. dag_id=bigdata_tp, task_id=TopCTR, execution_date=20230507T185619, start_date=20230507T185631, end_date=20230507T185631
[2023-05-07T15:56:31.533-0300] {standard_task_runner.py:100} ERROR - Failed to execute job 66 for task TopCTR ('sum'; 2195)
[2023-05-07T15:56:31.553-0300] {local_task_job.py:212} INFO - Task exited with return code 1
[2023-05-07T15:56:31.573-0300] {taskinstance.py:2596} INFO - 0 downstream tasks scheduled from follow-on schedule check
